<?xml version='1.0'?>
<gazebo version='1.2'>
  <model name="my_robot">
   <link name='chassis'>
      <pose>0 0 .1 0 0 0</pose>
      <collision name='collision'>
        <geometry>
          <box>
            <size>.4 .2 .1</size>
          </box>
        </geometry>
        <surface>
				<contact>
					<ode><max_vel>0</max_vel></ode>
				</contact>
        </surface>
      </collision>

        <inertial>
            <pose>0 0 0.1 0 0 0</pose>
            <inertia>
                <ixx>0.01</ixx>
                <ixy>0</ixy>
                <ixz>0</ixz>
                <iyy>0.01</iyy>
                <iyz>0</iyz>
                <izz>0.01</izz>
            </inertia>
            <mass>10.0</mass>
        </inertial>

      <visual name='visual'>
        <geometry>
          <box>
            <size>.4 .2 .1</size>
          </box>
        </geometry>
      </visual>

      <collision name='caster_collision'>
        <pose>-0.15 0 -0.05 0 0 0</pose>
        <geometry>
          <sphere>
          <radius>.05</radius>
        	</sphere>
      	</geometry>

      <surface>
        <friction>
          <ode>
            <mu>0</mu>
            <mu2>0</mu2>
            <slip1>1.0</slip1>
            <slip2>1.0</slip2>
          </ode>
        </friction>

				<contact>
					<ode><max_vel>0</max_vel></ode>
				</contact>
      </surface>
    </collision>

    <visual name='caster_visual'>
      <pose>-0.15 0 -0.05 0 0 0</pose>
      <geometry>
        <sphere>
          <radius>.05</radius>
        </sphere>
      </geometry>
    </visual>

       <visual name='cam_visual'>
	 <pose>0 0 0.5 0 0 0</pose>
         <geometry>
           <box>
             <size>0.100000 0.100000 0.100000</size>
           </box>
         </geometry>
       </visual>
       <sensor name='camera' type='camera'>
	 <pose>0 0 0.5 0 -0.1 3.14</pose>
	 <topic>kuukulgur_cam/image</topic>
	 <plugin name="kulgurcam" filename="libgazebo_ros_camera.so"/>
         <camera>
           <horizontal_fov>1.047000</horizontal_fov>
           <image>
             <width>320</width>
             <height>240</height>
           </image>
           <clip>
             <near>0.100000</near>
             <far>100.000000</far>
           </clip>
         </camera>
         <always_on>1</always_on>
         <update_rate>30.000000</update_rate>
         <visualize>1</visualize>
       </sensor>
  </link>     
  <link name="left_wheel">
    <pose>0.1 0.13 0.1 0 1.5707 1.5707</pose>
    <collision name="collision">
      <geometry>
        <cylinder>
          <radius>.1</radius>
          <length>.05</length>
        </cylinder>
      </geometry>

			<surface>
				<contact>
					<ode><max_vel>0</max_vel></ode>
				</contact>
			</surface>
    </collision>
    <visual name="visual">
      <geometry>
        <cylinder>
          <radius>.1</radius>
          <length>.05</length>
        </cylinder>
      </geometry>
    </visual>
  </link>

  <link name="right_wheel">
    <pose>0.1 -0.13 0.1 0 1.5707 1.5707</pose>
    <collision name="collision">
      <geometry>
        <cylinder>
          <radius>.1</radius>
          <length>.05</length>
        </cylinder>
      </geometry>
			<surface>
				<contact>
					<ode><max_vel>0</max_vel></ode>
				</contact>
			</surface>
    </collision>

    <visual name="visual">
      <geometry>
        <cylinder>
          <radius>.1</radius>
          <length>.05</length>
        </cylinder>
      </geometry>
    </visual>
  </link>
  <joint type="revolute" name="left_wheel_hinge">
    <pose>0 0 -0.03 0 0 0</pose>
    <child>left_wheel</child>
    <parent>chassis</parent>
    <axis>
      <xyz>0 1 0</xyz>
    </axis>
  </joint>

  <joint type="revolute" name="right_wheel_hinge">
    <pose>0 0 0.03 0 0 0</pose>
    <child>right_wheel</child>
    <parent>chassis</parent>
    <axis>
      <xyz>0 1 0</xyz>
    </axis>
  </joint>

 


   </model>
</gazebo>
